Workbook
Name RESOURCE: Resources!$B$1:$B$10
Name RESOURCETYPE: Helpers!$E$2:$E$4
Name Status: Helpers!$A$2:$A$6

Sheet Project Dashboard
B1: Project Overview
A2: Project Name | B2: Agent App
A3: Work order | B3: W01022022
A4: Client | B4: Internal Project
A5: Start Date | B5: 21/02/2022

Sheet Project Estimates
A1: PMID | B1: Defined Goals/Project Milestones | C1: User Story | D1: Total Count | E1: Optimistic | F1: Most Likely | G1: Pessimistic | H1: Man Days | I1: Man hours | J1: Completed Tasks | K1: Billing($) | L1: Mandays per task | M1: Actual Cost($)
A2: PMID001 | B2: Add properties with timer to delete | C2: As an agent I would like to add properties with a specific timer so that it may be deleted when the time is up. | D2: =SUMIF('Sprint Planner'!A:A,'Project Estimates'!A2,'Sprint Planner'!E:E) -> 4 | E2: 3 | F2: 4 | G2: 5 | H2: =(E2+(F2*4)+G2)/6 -> 4 | I2: =H2*8 -> 32 | J2: =SUMIFS('Sprint Planner'!E:E,'Sprint Planner'!A:A,'Project Estimates'!A2,'Sprint Planner'!H:H,"COMPLETED") -> 2 | K2: =L2*8*J2*Helpers!$C$2 -> 480 | L2: =H2/D2 -> 1 | M2: =IF(SUMIF('Sprint Planner'!A:A, 'Project Estimates'!A2,'Sprint Planner'!G:G)>0, SUMIF('Sprint Planner'!A:A, 'Project Estimates'!A2,'Sprint Planner'!G:G)*8*Helpers!C2,"") -> 480
A3: PMID002 | B3: Commission input on New Listing | C3: As an agent I would like to add new listing with specific commission so that other agents may be aware of the incentive on sales | D3: =SUMIF('Sprint Planner'!A:A,'Project Estimates'!A3,'Sprint Planner'!E:E) -> 2 | E3: 2 | F3: 3 | G3: 5 | H3: =(E3+(F3*4)+G3)/6 -> 3.1666667 | I3: =H3*8 -> 25.333333 | J3: =SUMIFS('Sprint Planner'!E:E,'Sprint Planner'!A:A,'Project Estimates'!A3,'Sprint Planner'!H:H,"COMPLETED") -> 0 | K3: =L3*8*J3*Helpers!$C$2 -> 0 | L3: =H3/D3 -> 1.5833333 | M3: =IF(SUMIF('Sprint Planner'!A:A, 'Project Estimates'!A3,'Sprint Planner'!G:G)>0, SUMIF('Sprint Planner'!A:A, 'Project Estimates'!A3,'Sprint Planner'!G:G)*8*Helpers!C3,"")
A4: PMID003 | B4: Master Account | C4: As an administrator I would like to create a Master Account that enables me to impersonate users and do actions on their behalf. | D4: =SUMIF('Sprint Planner'!A:A,'Project Estimates'!A4,'Sprint Planner'!E:E) -> 4 | E4: 5 | F4: 7 | G4: 10 | H4: =(E4+(F4*4)+G4)/6 -> 7.1666667 | I4: =H4*8 -> 57.333333 | J4: =SUMIFS('Sprint Planner'!E:E,'Sprint Planner'!A:A,'Project Estimates'!A4,'Sprint Planner'!H:H,"COMPLETED") -> 0 | K4: =L4*8*J4*Helpers!$C$2 -> 0 | L4: =H4/D4 -> 1.7916667 | M4: =IF(SUMIF('Sprint Planner'!A:A, 'Project Estimates'!A4,'Sprint Planner'!G:G)>0, SUMIF('Sprint Planner'!A:A, 'Project Estimates'!A4,'Sprint Planner'!G:G)*8*Helpers!C4,"")
A5: PMID004 | B5: Neighborhood Search Ability | C5: As an agent I would like to search by neighbourhood so that I may be able to look up avaialble properties in the vicinity | D5: =SUMIF('Sprint Planner'!A:A,'Project Estimates'!A5,'Sprint Planner'!E:E) -> 3 | E5: 1 | F5: 2 | G5: 3 | H5: =(E5+(F5*4)+G5)/6 -> 2 | I5: =H5*8 -> 16 | J5: =SUMIFS('Sprint Planner'!E:E,'Sprint Planner'!A:A,'Project Estimates'!A5,'Sprint Planner'!H:H,"COMPLETED") -> 0 | K5: =L5*8*J5*Helpers!$C$2 -> 0 | L5: =H5/D5 -> 0.66666667 | M5: =IF(SUMIF('Sprint Planner'!A:A, 'Project Estimates'!A5,'Sprint Planner'!G:G)>0, SUMIF('Sprint Planner'!A:A, 'Project Estimates'!A5,'Sprint Planner'!G:G)*8*Helpers!C5,"")
A6: PMID005 | B6: Street view accessible through map view | C6: As an agent I want a feature to be able to zoom into property and check out the street view so I may be able to view the locality and neighbourhood. | D6: =SUMIF('Sprint Planner'!A:A,'Project Estimates'!A6,'Sprint Planner'!E:E) -> 1 | E6: 1 | F6: 2 | G6: 3 | H6: =(E6+(F6*4)+G6)/6 -> 2 | I6: =H6*8 -> 16 | J6: =SUMIFS('Sprint Planner'!E:E,'Sprint Planner'!A:A,'Project Estimates'!A6,'Sprint Planner'!H:H,"COMPLETED") -> 0 | K6: =L6*8*J6*Helpers!$C$2 -> 0 | L6: =H6/D6 -> 2 | M6: =IF(SUMIF('Sprint Planner'!A:A, 'Project Estimates'!A6,'Sprint Planner'!G:G)>0, SUMIF('Sprint Planner'!A:A, 'Project Estimates'!A6,'Sprint Planner'!G:G)*8*Helpers!C6,"")
A7: PMID006 | B7: Scroll up photo header on listings | C7: As an agent I wish to have the property address and details as static header and a scrollable details view so that I may be able to see the current property details in view. | D7: 2 | E7: 3 | F7: 5 | G7: 7 | H7: =(E7+(F7*4)+G7)/6 -> 5 | I7: =H7*8 -> 40 | J7: =SUMIFS('Sprint Planner'!E:E,'Sprint Planner'!A:A,'Project Estimates'!A7,'Sprint Planner'!H:H,"COMPLETED") -> 0 | K7: =L7*8*J7*Helpers!$C$2 -> 0 | L7: =H7/D7 -> 2.5 | M7: =IF(SUMIF('Sprint Planner'!A:A, 'Project Estimates'!A7,'Sprint Planner'!G:G)>0, SUMIF('Sprint Planner'!A:A, 'Project Estimates'!A7,'Sprint Planner'!G:G)*8*Helpers!C7,"")
A8: PMID007 | B8: Click in photos from header | C8: As an agent I would like to view all photos on a gallery view on right swipe of property details view so that I can quickly swich between details and photos | D8: =SUMIF('Sprint Planner'!A:A,'Project Estimates'!A8,'Sprint Planner'!E:E) -> 2 | E8: 2 | F8: 3 | G8: 5 | H8: =(E8+(F8*4)+G8)/6 -> 3.1666667 | I8: =H8*8 -> 25.333333 | J8: =SUMIFS('Sprint Planner'!E:E,'Sprint Planner'!A:A,'Project Estimates'!A8,'Sprint Planner'!H:H,"COMPLETED") -> 0 | K8: =L8*8*J8*Helpers!$C$2 -> 0 | L8: =H8/D8 -> 1.5833333 | M8: =IF(SUMIF('Sprint Planner'!A:A, 'Project Estimates'!A8,'Sprint Planner'!G:G)>0, SUMIF('Sprint Planner'!A:A, 'Project Estimates'!A8,'Sprint Planner'!G:G)*8*Helpers!C8,"")
A9: PMID008 | B9: Truncating Description | C9: As an agent I would like to update all descriptions with (Read more/Read less icons) to show a brief of the descriptions in View Property Details and View Buyer Requirements so that more relevant content may not be obscured. | D9: 2 | E9: 2 | F9: 3 | G9: 5 | H9: =(E9+(F9*4)+G9)/6 -> 3.1666667 | I9: =H9*8 -> 25.333333 | J9: =SUMIFS('Sprint Planner'!E:E,'Sprint Planner'!A:A,'Project Estimates'!A9,'Sprint Planner'!H:H,"COMPLETED") -> 0 | K9: =L9*8*J9*Helpers!$C$2 -> 0 | L9: =H9/D9 -> 1.5833333 | M9: =IF(SUMIF('Sprint Planner'!A:A, 'Project Estimates'!A9,'Sprint Planner'!G:G)>0, SUMIF('Sprint Planner'!A:A, 'Project Estimates'!A9,'Sprint Planner'!G:G)*8*Helpers!C9,"")
A10: PMID009 | B10: Swipe through photos | C10: As an agent I would like view search and see results on map to swipe through all properties on a map by appending a property view, and similar swipe through all photo views on property details so that the agent can quick view all related properties and photos. | D10: 2 | E10: 5 | F10: 10 | G10: 15 | H10: =(E10+(F10*4)+G10)/6 -> 10 | I10: =H10*8 -> 80 | J10: =SUMIFS('Sprint Planner'!E:E,'Sprint Planner'!A:A,'Project Estimates'!A10,'Sprint Planner'!H:H,"COMPLETED") -> 0 | K10: =L10*8*J10*Helpers!$C$2 -> 0 | L10: =H10/D10 -> 5 | M10: =IF(SUMIF('Sprint Planner'!A:A, 'Project Estimates'!A10,'Sprint Planner'!G:G)>0, SUMIF('Sprint Planner'!A:A, 'Project Estimates'!A10,'Sprint Planner'!G:G)*8*Helpers!C10,"")
A11: PMID010 | B11: Notification settings | C11: As an agent I want to have the feauter to turn off push notifications and select email notification interval so that I can select my preference of receiving emails. | D11: 6 | E11: 4 | F11: 7 | G11: 10 | H11: =(E11+(F11*4)+G11)/6 -> 7 | I11: =H11*8 -> 56 | J11: =SUMIFS('Sprint Planner'!E:E,'Sprint Planner'!A:A,'Project Estimates'!A11,'Sprint Planner'!H:H,"COMPLETED") -> 0 | K11: =L11*8*J11*Helpers!$C$2 -> 0 | L11: =H11/D11 -> 1.1666667 | M11: =IF(SUMIF('Sprint Planner'!A:A, 'Project Estimates'!A11,'Sprint Planner'!G:G)>0, SUMIF('Sprint Planner'!A:A, 'Project Estimates'!A11,'Sprint Planner'!G:G)*8*Helpers!C11,"")
A12: PMID011 | B12: Skip Add Client Contact Details | C12: As an agent, I would like to add properites or buyer requirements without providing contact details so that I may be able to skip email, messenger or phone contact option. | D12: 8 | E12: 6 | F12: 12 | G12: 18 | H12: =(E12+(F12*4)+G12)/6 -> 12 | I12: =H12*8 -> 96 | J12: =SUMIFS('Sprint Planner'!E:E,'Sprint Planner'!A:A,'Project Estimates'!A12,'Sprint Planner'!H:H,"COMPLETED") -> 0 | K12: =L12*8*J12*Helpers!$C$2 -> 0 | L12: =H12/D12 -> 1.5 | M12: =IF(SUMIF('Sprint Planner'!A:A, 'Project Estimates'!A12,'Sprint Planner'!G:G)>0, SUMIF('Sprint Planner'!A:A, 'Project Estimates'!A12,'Sprint Planner'!G:G)*8*Helpers!C12,"")
A13: PMID012 | B13: Remove User Name field from Sign Up | C13: As a voyage user I wish to remove user name in luie of email address provided as login credential so that username is no longer a requirement for creating an account | D13: 1 | E13: 0.5 | F13: 1 | G13: 1.5 | H13: =(E13+(F13*4)+G13)/6 -> 1 | I13: =H13*8 -> 8 | J13: =SUMIFS('Sprint Planner'!E:E,'Sprint Planner'!A:A,'Project Estimates'!A13,'Sprint Planner'!H:H,"COMPLETED") -> 0 | K13: =L13*8*J13*Helpers!$C$2 -> 0 | L13: =H13/D13 -> 1 | M13: =IF(SUMIF('Sprint Planner'!A:A, 'Project Estimates'!A13,'Sprint Planner'!G:G)>0, SUMIF('Sprint Planner'!A:A, 'Project Estimates'!A13,'Sprint Planner'!G:G)*8*Helpers!C13,"")
A14: PMID013 | B14: Terms of Service in Sign Up Linked incorrectly | C14: As a voyage user I wish to update both ToC and Privacy policy mapped properly so that any ambigutiy is addressed. | D14: =SUMIF('Sprint Planner'!A:A,'Project Estimates'!A14,'Sprint Planner'!E:E) -> 1 | E14: 0.5 | F14: 1 | G14: 1.5 | H14: =(E14+(F14*4)+G14)/6 -> 1 | I14: =H14*8 -> 8 | J14: =SUMIFS('Sprint Planner'!E:E,'Sprint Planner'!A:A,'Project Estimates'!A14,'Sprint Planner'!H:H,"COMPLETED") -> 0 | K14: =L14*8*J14*Helpers!$C$2 -> 0 | L14: =H14/D14 -> 1 | M14: =IF(SUMIF('Sprint Planner'!A:A, 'Project Estimates'!A14,'Sprint Planner'!G:G)>0, SUMIF('Sprint Planner'!A:A, 'Project Estimates'!A14,'Sprint Planner'!G:G)*8*Helpers!C14,"")
A15: PMID014 | B15: Share listing with client | C15: As an agent I wish to have the "Share link" feature so that I may be able to freely share any property with others in the team by email or messenger. | D15: 2 | E15: 2 | F15: 3 | G15: 5 | H15: =(E15+(F15*4)+G15)/6 -> 3.1666667 | I15: =H15*8 -> 25.333333 | J15: =SUMIFS('Sprint Planner'!E:E,'Sprint Planner'!A:A,'Project Estimates'!A15,'Sprint Planner'!H:H,"COMPLETED") -> 0 | K15: =L15*8*J15*Helpers!$C$2 -> 0 | L15: =H15/D15 -> 1.5833333 | M15: =IF(SUMIF('Sprint Planner'!A:A, 'Project Estimates'!A15,'Sprint Planner'!G:G)>0, SUMIF('Sprint Planner'!A:A, 'Project Estimates'!A15,'Sprint Planner'!G:G)*8*Helpers!C15,"")
A16: PMID015 | B16: Client Tab | C16: As an agent, I want to have a client tab, so that I may be able to see my clients and their associated properties or requirements. | D16: =SUMIF('Sprint Planner'!A:A,'Project Estimates'!A16,'Sprint Planner'!E:E) -> 2 | E16: 3 | F16: 5 | G16: 7 | H16: =(E16+(F16*4)+G16)/6 -> 5 | I16: =H16*8 -> 40 | J16: =SUMIFS('Sprint Planner'!E:E,'Sprint Planner'!A:A,'Project Estimates'!A16,'Sprint Planner'!H:H,"COMPLETED") -> 0 | K16: =L16*8*J16*Helpers!$C$2 -> 0 | L16: =H16/D16 -> 2.5 | M16: =IF(SUMIF('Sprint Planner'!A:A, 'Project Estimates'!A16,'Sprint Planner'!G:G)>0, SUMIF('Sprint Planner'!A:A, 'Project Estimates'!A16,'Sprint Planner'!G:G)*8*Helpers!C16,"")
A17: PMID016 | B17: Add Contacts from Phone | C17: As an agent I need to have the option to import my contacts from my phone so I can associate with properties and requirements. | D17: 2 | E17: 3 | F17: 5 | G17: 7 | H17: =(E17+(F17*4)+G17)/6 -> 5 | I17: =H17*8 -> 40 | J17: =SUMIFS('Sprint Planner'!E:E,'Sprint Planner'!A:A,'Project Estimates'!A17,'Sprint Planner'!H:H,"COMPLETED") -> 0 | K17: =L17*8*J17*Helpers!$C$2 -> 0 | L17: =H17/D17 -> 2.5 | M17: =IF(SUMIF('Sprint Planner'!A:A, 'Project Estimates'!A17,'Sprint Planner'!G:G)>0, SUMIF('Sprint Planner'!A:A, 'Project Estimates'!A17,'Sprint Planner'!G:G)*8*Helpers!C17,"")

Sheet Sprint Planner
A1: PMID | B1: Sprint | C1: Task Id | D1: Task Description | E1: Units Assigned | F1: Start Date | G1: Duration | H1: Status | I1: Completed Date | J1: Job Assignment
A2: Sprint 1 (22-03-2021)
A3: PMID001 | C3: T1001 | D3: Create a CRON job to validate active property timers at regular intervals. | E3: 1 | F3: 44594 | G3: =IF(I3-F3>0, I3-F3, "") -> 1 | H3: COMPLETED | I3: 44595 | J3: Senior Java Developer
A4: PMID001 | C4: T1002 | D4: Update property table to create new purge record date-time and update new version of API (New Property/Update Property/View Property) | E4: 1 | F4: 44594 | G4: =IF(I4-F4>0, I4-F4, "") -> 1 | H4: COMPLETED | I4: 44595 | J4: Senior Java Developer
A5: PMID001 | C5: T1003 | D5: Update UI to add property option to purge records if checked on specifed data-time on pages (Add Property/Edit Property/View Property) | E5: 1 | F5: 44596 | G5: =IF(I5-F5>0, I5-F5, "") | J5: Frontend Developer
A6: PMID001 | C6: T1004 | D6: Update UI to update property option to purge records if checked on specifed data-time. | E6: 1 | G6: =IF(I6-F6>0, I6-F6, "") | J6: Frontend Developer
A7: Sprint 2
A8: PMID002 | C8: T1005 | D8: Update DB with commission_on_sales field, update API (Add Property/Edit Property/View Property) | E8: 1 | G8: =IF(I8-F8>0, I8-F8, "")
A9: PMID002 | C9: T1006 | D9: Update UI to include commission on sales to (Add Property/Edit Property/View Property pages) | E9: 1 | G9: =IF(I9-F9>0, I9-F9, "")
A10: Sprint 3
A11: PMID003 | C11: T1007 | D11: Create new Role SuperAdmin | E11: 1 | G11: =IF(I11-F11>0, I11-F11, "")
A12: PMID003 | C12: T1008 | D12: Create API to swich user and log in activity as superadmin acting as X for every transaction with key signature for auditing. Add API header for impersonated user with superadmin and log to activity. | E12: 1 | G12: =IF(I12-F12>0, I12-F12, "")
A13: PMID003 | C13: T1009 | D13: Create UI for superadmin account switch user panel with list of users as dropdown. | E13: 1 | G13: =IF(I13-F13>0, I13-F13, "")
A14: PMID003 | C14: T1010 | D14: Create a UI header tag SuperAdmin (X User) if impersonation is active. | E14: 1 | G14: =IF(I14-F14>0, I14-F14, "")
A15: Sprint 4
A16: PMID004 | C16: T1011 | D16: Create search API to search by neighbour hood (keyword match) | E16: 1 | G16: =IF(I16-F16>0, I16-F16, "")
A17: PMID004 | C17: T1012 | D17: Identify if neighbourhood or keyword search is suppored by MLS and integrate the same | E17: 1 | G17: =IF(I17-F17>0, I17-F17, "")
A18: PMID004 | C18: T1013 | D18: Update UI to allow new search by Neighbourhood (cosmetic chages to labels) | E18: 1 | G18: =IF(I18-F18>0, I18-F18, "")
A19: Sprint 5
A20: PMID005 | C20: T1014 | D20: Map view to include integration with street view on property popup or street view marker in popup. | E20: 1 | G20: =IF(I20-F20>0, I20-F20, "")
A21: Sprint 6
A22: PMID006 | C22: T1015 | D22: In View Property Details add Header and scrollable content view | E22: 1 | G22: =IF(I22-F22>0, I22-F22, "")
A23: PMID006 | C23: T1016 | D23: In View Buyer Requirement Details add Header and scrollable content view | E23: 1 | G23: =IF(I23-F23>0, I23-F23, "")
A24: Sprint 7
A25: PMID007 | C25: T1017 | D25: Create new right swipe gallery section in property details view | E25: 1 | G25: =IF(I25-F25>0, I25-F25, "")
A26: PMID007 | C26: T1018 | D26: Create a new gallery to show thumbnails of all photos with click to view option. | E26: 1 | G26: =IF(I26-F26>0, I26-F26, "")
A27: Sprint 8
A28: PMID008 | C28: T1019 | D28: Update property detail view descriptions with script to handle read more/read less based on content length | E28: 1 | G28: =IF(I28-F28>0, I28-F28, "")
A29: PMID008 | C29: T1020 | D29: Update buyer requirement view descriptonis with script to handle read more/read less based on content length | E29: 1 | G29: =IF(I29-F29>0, I29-F29, "")
A30: Sprint 9
A31: PMID009 | C31: T1021 | D31: Update map view with images of properties in the current view which can be swiped though the image area below the map | E31: 1 | G31: =IF(I31-F31>0, I31-F31, "")
A32: PMID009 | C32: T1022 | D32: Update property details view with all photos loaded in the image view that can be swiped to the next consequtive image of the property | E32: 1 | G32: =IF(I32-F32>0, I32-F32, "")
A33: Sprint 10
A34: PMID010 | C34: T1023 | D34: Create a mail_notification table and add mailing_interval_preference (daily/weekly/monthly) in contact table | E34: 1 | G34: =IF(I34-F34>0, I34-F34, "")
A35: PMID010 | C35: T1024 | D35: Remove current email dispatch function and replace with store email to email_digest table | E35: 1 | G35: =IF(I35-F35>0, I35-F35, "")
A36: PMID010 | C36: T1025 | D36: Create a Cron job to check schdule and dispatch email based on preference (daily/weekly) | E36: 1 | G36: =IF(I36-F36>0, I36-F36, "")
A37: PMID010 | C37: T1026 | D37: Create a new field is_push_notification_enabled in contact table | E37: 1 | G37: =IF(I37-F37>0, I37-F37, "")
A38: PMID010 | C38: T1027 | D38: Update current push notification model to validate if push_notificaiton is enabled before posting | E38: 1 | G38: =IF(I38-F38>0, I38-F38, "")
A39: PMID010 | C39: T1028 | D39: In UI user profile create new push_notification and mail_interval_presence fields and also update the same in registration forms and add client screens | E39: 1 | G39: =IF(I39-F39>0, I39-F39, "")
A40: Sprint 11
...

Sheet Resources
A1: # | B1: Resource Name | C1: Resource Type | D1: Designation | E1: Assigned Tasks | F1: Current Tasks | G1: Completed Tasks
A2: 1 | B2: Architect | C2: STAFF | D2: Architect | E2: =SUMIFS( 'Sprint Planner'!E:E,'Sprint Planner'!J:J, Resources!B2) -> 0 | F2: =SUMIFS('Sprint Planner'!E:E, 'Sprint Planner'!J:J, Resources!B2,'Sprint Planner'!H:H,"IN-PROGRESS" ) -> 0 | G2: =SUMIFS( 'Sprint Planner'!E:E,'Sprint Planner'!J:J, Resources!B2, 'Sprint Planner'!H:H, "COMPLETED") -> 0
A3: 2 | B3: Senior Java Developer | C3: STAFF | D3: AWS Senior Engineer | E3: =SUMIFS( 'Sprint Planner'!E:E,'Sprint Planner'!J:J, Resources!B3) -> 2 | F3: =SUMIFS( 'Sprint Planner'!E:E,'Sprint Planner'!J:J, Resources!B3, 'Sprint Planner'!H:H, "IN-PROGRESS") -> 0 | G3: =SUMIFS( 'Sprint Planner'!E:E,'Sprint Planner'!J:J, Resources!B3, 'Sprint Planner'!H:H, "COMPLETED") -> 2
A4: 3 | B4: Frontend Developer | C4: STAFF | D4: React Native Developer | E4: =SUMIFS( 'Sprint Planner'!E:E,'Sprint Planner'!J:J, Resources!B4) -> 2 | F4: =SUMIFS( 'Sprint Planner'!E:E,'Sprint Planner'!J:J, Resources!B4, 'Sprint Planner'!H:H, "IN-PROGRESS") -> 0 | G4: =SUMIFS( 'Sprint Planner'!E:E,'Sprint Planner'!J:J, Resources!B4, 'Sprint Planner'!H:H, "COMPLETED") -> 0
A5: 4 | B5: UX Designer | C5: STAFF | D5: Designer | E5: =SUMIFS( 'Sprint Planner'!E:E,'Sprint Planner'!J:J, Resources!B5) -> 0 | F5: =SUMIFS( 'Sprint Planner'!E:E,'Sprint Planner'!J:J, Resources!B5, 'Sprint Planner'!H:H, "IN-PROGRESS") -> 0 | G5: =SUMIFS( 'Sprint Planner'!E:E,'Sprint Planner'!J:J, Resources!B5, 'Sprint Planner'!H:H, "COMPLETED") -> 0
A6: 5 | B6: Test Engineer | C6: CONTRACTOR | D6: App Tester

Sheet Helpers
A1: Project Status | C1: Cost per Hour ($) | E1: Resource Type
A2: IN-PROGRESS | C2: 30 | E2: STAFF
A3: ON-HOLD | E3: CONTRACTOR
A4: CANCELLED | E4: AGENCY
A5: WITHDRAWN
A6: COMPLETED
