Workbook
Name RESOURCE: Resources!$B$1:$B$10
Name RESOURCETYPE: Helpers!$E$2:$E$4
Name Status: Helpers!$A$2:$A$6

Sheet Project Dashboard
B1: Project Overview
A2: Project Name | B2: Sistema de Gestion de Pedidos y Clientes (doc.md)
A3: Work order | B3: EXP-2026-CAS-01
A4: Client | B4: UNSA - Calidad de Software
A5: Start Date | B5: 28/09/2026

Sheet Project Estimates
A1: PMID | B1: Defined Goals/Project Milestones | C1: User Story | D1: Total Count | E1: Optimistic | F1: Most Likely | G1: Pessimistic | H1: Man Days | I1: Man hours | J1: Completed Tasks | K1: Billing($) | L1: Mandays per task | M1: Actual Cost($)
A2: PMID001 | B2: Registro y administracion de clientes | C2: Como administrador requiero registrar y actualizar datos de clientes naturales y juridicos. | D2: 1 | E2: 6 | F2: 10 | G2: 16 | H2: =(E2+4*F2+G2)/6 | I2: =H2*8
A3: PMID002 | B3: Gestion de cuentas comerciales | C3: Como administrador requiero aperturar y configurar lineas de cuenta comercial para facturacion. | D3: 1 | E3: 5 | F3: 9 | G3: 15 | H3: =(E3+4*F3+G3)/6 | I3: =H3*8
A4: PMID003 | B4: Catalogo maestro de productos | C4: Como gestor comercial requiero administrar el catalogo de productos, precios y categorias. | D4: 1 | E4: 6 | F4: 10 | G4: 18 | H4: =(E4+4*F4+G4)/6 | I4: =H4*8
A5: PMID004 | B5: Registro de pedidos simples | C5: Como cliente/vendedor requiero registrar ordenes de pedido individuales con calculo de impuestos. | D5: 1 | E5: 7 | F5: 12 | G5: 20 | H5: =(E5+4*F5+G5)/6 | I5: =H5*8
A6: PMID005 | B6: Composicion de pedidos compuestos | C6: Como usuario requiero agrupar pedidos multinivel con reglas de consolidacion de entrega. | D6: 1 | E6: 8 | F6: 14 | G6: 22 | H6: =(E6+4*F6+G6)/6 | I6: =H6*8
A7: PMID006 | B7: Validacion de credito e inventario | C7: Como sistema requiero verificar limites crediticios y disponibilidad de stock en tiempo real. | D7: 1 | E7: 6 | F7: 11 | G7: 18 | H7: =(E7+4*F7+G7)/6 | I7: =H7*8
A8: PMID007 | B8: Modulo de cobro y pasarela de pago | C8: Como cliente requiero ejecutar cobros automaticos con tarjetas y transferencias integradas. | D8: 1 | E8: 8 | F8: 13 | G8: 21 | H8: =(E8+4*F8+G8)/6 | I8: =H8*8
A9: PMID008 | B9: Emision de comprobantes electronicos | C9: Como sistema requiero emitir y timbrar facturas y boletas electronicas validadas por SUNAT. | D9: 1 | E9: 6 | F9: 10 | G9: 16 | H9: =(E9+4*F9+G9)/6 | I9: =H9*8
A10: PMID009 | B10: Despacho y seguimiento logistico | C10: Como despachador requiero programar la guia de remision y actualizar estado de envio. | D10: 1 | E10: 5 | F10: 9 | G10: 15 | H10: =(E10+4*F10+G10)/6 | I10: =H10*8
A11: PMID010 | B11: Reportes y auditoria comercial | C11: Como supervisor requiero emitir reportes consolidados de cuentas por cobrar y balance. | D11: 1 | E11: 6 | F11: 11 | G11: 17 | H11: =(E11+4*F11+G11)/6 | I11: =H11*8
B12: Total Esfuerzo Estimado (Man-Days) | H12: =SUM(H2:H11) | I12: =SUM(I2:I11)

Sheet Sprint Planner
A1: PMID | B1: Sprint | C1: Task Id | D1: Task Description | E1: Units Assigned | F1: Start Date | G1: Duration | H1: Status | I1: Completed Date | J1: Job Assignment
A2: Sprint 1 (22-03-2021)
A3: PMID001 | C3: T1001 | D3: Diseno de modelo relacional para clientes naturales y juridicos | E3: 1 | F3: 44594 | G3: =IF(I3-F3>0, I3-F3, "") | H3: COMPLETED | I3: 44595 | J3: Senior Java Developer
A4: PMID001 | C4: T1002 | D4: API REST de registro, validacion de RUC/DNI y actualizacion | E4: 1 | F4: 44594 | G4: =IF(I4-F4>0, I4-F4, "") | H4: COMPLETED | I4: 44595 | J4: Senior Java Developer
A5: PMID001 | C5: T1003 | D5: Interfaz de usuario para gestion y busqueda de clientes | E5: 1 | F5: 44596 | G5: =IF(I5-F5>0, I5-F5, "") | J5: Frontend Developer
A6: PMID001 | C6: T1004 | D6: Validacion de reglas de negocio y duplicidad de registros | E6: 1 | G6: =IF(I6-F6>0, I6-F6, "") | J6: Frontend Developer
A7: Sprint 2
A8: PMID002 | C8: T1005 | D8: Configuracion de lineas de credito comercial y cuentas | E8: 1 | G8: =IF(I8-F8>0, I8-F8, "")
A9: PMID002 | C9: T1006 | D9: Modulo de administracion de cuentas por cobrar y pagar | E9: 1 | G9: =IF(I9-F9>0, I9-F9, "")
A10: Sprint 3
A11: PMID003 | C11: T1007 | D11: Catalogo maestro de productos, precios y categorias | E11: 1 | G11: =IF(I11-F11>0, I11-F11, "")
A12: PMID003 | C12: T1008 | D12: Servicio de control de inventario y stock en tiempo real | E12: 1 | G12: =IF(I12-F12>0, I12-F12, "")
A13: PMID003 | C13: T1009 | D13: Interfaz de busqueda y navegacion de productos | E13: 1 | G13: =IF(I13-F13>0, I13-F13, "")
A14: PMID003 | C14: T1010 | D14: Control de lotes, almacenes y listas de precios | E14: 1 | G14: =IF(I14-F14>0, I14-F14, "")
A15: Sprint 4
A16: PMID004 | C16: T1011 | D16: Create search API to search by neighbour hood (keyword match) | E16: 1 | G16: =IF(I16-F16>0, I16-F16, "")
A17: PMID004 | C17: T1012 | D17: Identify if neighbourhood or keyword search is suppored by MLS and integrate the same | E17: 1 | G17: =IF(I17-F17>0, I17-F17, "")
A18: PMID004 | C18: T1013 | D18: Update UI to allow new search by Neighbourhood (cosmetic chages to labels) | E18: 1 | G18: =IF(I18-F18>0, I18-F18, "")
A19: Sprint 5
A20: PMID005 | C20: T1014 | D20: Map view to include integration with street view on property popup or street view marker in popup. | E20: 1 | G20: =IF(I20-F20>0, I20-F20, "")
A21: Sprint 6
A22: PMID006 | C22: T1015 | D22: In View Property Details add Header and scrollable content view | E22: 1 | G22: =IF(I22-F22>0, I22-F22, "")
A23: PMID006 | C23: T1016 | D23: In View Buyer Requirement Details add Header and scrollable content view | E23: 1 | G23: =IF(I23-F23>0, I23-F23, "")
A24: Sprint 7
A25: PMID007 | C25: T1017 | D25: Create new right swipe gallery section in property details view | E25: 1 | G25: =IF(I25-F25>0, I25-F25, "")
A26: PMID007 | C26: T1018 | D26: Create a new gallery to show thumbnails of all photos with click to view option. | E26: 1 | G26: =IF(I26-F26>0, I26-F26, "")
A27: Sprint 8
A28: PMID008 | C28: T1019 | D28: Update property detail view descriptions with script to handle read more/read less based on content length | E28: 1 | G28: =IF(I28-F28>0, I28-F28, "")
A29: PMID008 | C29: T1020 | D29: Update buyer requirement view descriptonis with script to handle read more/read less based on content length | E29: 1 | G29: =IF(I29-F29>0, I29-F29, "")
A30: Sprint 9
A31: PMID009 | C31: T1021 | D31: Update map view with images of properties in the current view which can be swiped though the image area below the map | E31: 1 | G31: =IF(I31-F31>0, I31-F31, "")
A32: PMID009 | C32: T1022 | D32: Update property details view with all photos loaded in the image view that can be swiped to the next consequtive image of the property | E32: 1 | G32: =IF(I32-F32>0, I32-F32, "")
A33: Sprint 10
A34: PMID010 | C34: T1023 | D34: Create a mail_notification table and add mailing_interval_preference (daily/weekly/monthly) in contact table | E34: 1 | G34: =IF(I34-F34>0, I34-F34, "")
A35: PMID010 | C35: T1024 | D35: Remove current email dispatch function and replace with store email to email_digest table | E35: 1 | G35: =IF(I35-F35>0, I35-F35, "")
A36: PMID010 | C36: T1025 | D36: Create a Cron job to check schdule and dispatch email based on preference (daily/weekly) | E36: 1 | G36: =IF(I36-F36>0, I36-F36, "")
A37: PMID010 | C37: T1026 | D37: Create a new field is_push_notification_enabled in contact table | E37: 1 | G37: =IF(I37-F37>0, I37-F37, "")
A38: PMID010 | C38: T1027 | D38: Update current push notification model to validate if push_notificaiton is enabled before posting | E38: 1 | G38: =IF(I38-F38>0, I38-F38, "")
A39: PMID010 | C39: T1028 | D39: In UI user profile create new push_notification and mail_interval_presence fields and also update the same in registration forms and add client screens | E39: 1 | G39: =IF(I39-F39>0, I39-F39, "")
A40: Sprint 11
...

Sheet Resources
A1: # | B1: Resource Name | C1: Resource Type | D1: Designation | E1: Assigned Tasks | F1: Current Tasks | G1: Completed Tasks
A2: 1 | B2: Architect | C2: STAFF | D2: Architect | E2: =SUMIFS( 'Sprint Planner'!E:E,'Sprint Planner'!J:J, Resources!B2) | F2: =SUMIFS('Sprint Planner'!E:E, 'Sprint Planner'!J:J, Resources!B2,'Sprint Planner'!H:H,"IN-PROGRESS" ) | G2: =SUMIFS( 'Sprint Planner'!E:E,'Sprint Planner'!J:J, Resources!B2, 'Sprint Planner'!H:H, "COMPLETED")
A3: 2 | B3: Senior Java Developer | C3: STAFF | D3: AWS Senior Engineer | E3: =SUMIFS( 'Sprint Planner'!E:E,'Sprint Planner'!J:J, Resources!B3) | F3: =SUMIFS( 'Sprint Planner'!E:E,'Sprint Planner'!J:J, Resources!B3, 'Sprint Planner'!H:H, "IN-PROGRESS") | G3: =SUMIFS( 'Sprint Planner'!E:E,'Sprint Planner'!J:J, Resources!B3, 'Sprint Planner'!H:H, "COMPLETED")
A4: 3 | B4: Frontend Developer | C4: STAFF | D4: React Native Developer | E4: =SUMIFS( 'Sprint Planner'!E:E,'Sprint Planner'!J:J, Resources!B4) | F4: =SUMIFS( 'Sprint Planner'!E:E,'Sprint Planner'!J:J, Resources!B4, 'Sprint Planner'!H:H, "IN-PROGRESS") | G4: =SUMIFS( 'Sprint Planner'!E:E,'Sprint Planner'!J:J, Resources!B4, 'Sprint Planner'!H:H, "COMPLETED")
A5: 4 | B5: UX Designer | C5: STAFF | D5: Designer | E5: =SUMIFS( 'Sprint Planner'!E:E,'Sprint Planner'!J:J, Resources!B5) | F5: =SUMIFS( 'Sprint Planner'!E:E,'Sprint Planner'!J:J, Resources!B5, 'Sprint Planner'!H:H, "IN-PROGRESS") | G5: =SUMIFS( 'Sprint Planner'!E:E,'Sprint Planner'!J:J, Resources!B5, 'Sprint Planner'!H:H, "COMPLETED")
A6: 5 | B6: Test Engineer | C6: CONTRACTOR | D6: App Tester

Sheet Helpers
A1: Project Status | C1: Cost per Hour ($) | E1: Resource Type
A2: IN-PROGRESS | C2: 30 | E2: STAFF
A3: ON-HOLD | E3: CONTRACTOR
A4: CANCELLED | E4: AGENCY
A5: WITHDRAWN
A6: COMPLETED
